Workbook

Sheet README
A1: Biopunk Housing — composite ranked tracker
A2: Built Aug 22, 2026 from: Incubator Housing Report (Jul 16, 5 research rounds), cost dashboard, master contact sheet, Giulia/Alex Notion tracker, and the May 2026 house-hunt sheet.
A4: TABS
A5: Weights — the scoring inputs (yellow cells). Change a weight and every score on Pipeline and Inventory recalculates.
A6: Pipeline — whole buildings / master-lease targets for the 40–50 person program (Elliot + Ria work this tab). Ranked by Score.
A7: Inventory — bookable beds already operating in SF (from the Notion tracker). This is what incoming founders can use today and the seed for the live portal.
A8: Contacts — every phone/email from the contact sheet, with section. ⚠ = verify by phone before relying on it.
A9: Outreach log — one row per touch. Fill it in; the portal will read outreach status from here.
A10: Templates — email + call scripts, scaled up from the team's existing Gener/Sironi template.
A12: SCORING (0–100, criteria in the order the team stated them)
A13: Transit to Frontier (995 Market): full points ≤10 min walk, 0 at ≥45 min; East Bay / Peninsula / North Bay / Remote = 0.
A14: Price per bed: full points ≤ target ($1,000), linear to 0 at $2,200. Blank price = 5 pts (unknown).
... A23: Priority neighborhoods: SoMa, Nob Hill, Civic Center, FiDi, Union Square, NoPa/Panhandle. East Bay ruled out (too far from Frontier) — rows kept, scored 0 on transit.

Sheet Weights
A1: Input | B1: Value
A2: Transit weight (pts) | B2: 35
A3: Price weight (pts) | B3: 30
A4: Kitchen weight (pts) | B4: 15
A5: Bed-fit weight (pts) | B5: 20
A6: Target $/bed (full price points at or below) | B6: 1000
A7: Max $/bed (0 price points at or above) | B7: 2200
A8: Walk min for full transit points | B8: 10
A9: Walk min for 0 transit points | B9: 45
A10: Sept-15-ready bonus (pts) | B10: 5
A11: Tourist-hotel no-kitchen cap | B11: 40
A12: Cohort size for monthly estimate | B12: 45
A13: Ideal beds low | B13: 40
A14: Ideal beds high | B14: 60
A16: Yellow cells are the only inputs. Weights should sum to 100. Source: team criteria from the Aug 2026 planning call (transit, price, kitchen, bed count) and the Jul 2026 report's budget math.

Sheet Pipeline
A1: Rank | B1: Name | C1: Address | D1: Neighborhood | E1: Region | F1: Walk min to Frontier (est) | G1: Walk source | H1: Type | I1: Rooms / units | J1: Occ. per room | K1: Beds est | L1: $/room low | M1: $/room high | N1: $/bed est | O1: Monthly for cohort ($) | P1: Kitchen | Q1: Status | R1: Source tier | S1: Timeline tags | T1: Sept-15 ready? | U1: AAU? | V1: Baseline? | W1: Price / ask (as sourced) | X1: The play | Y1: Contact | Z1: Phone | AA1: Email / path | AB1: Contact section | AC1: Source links | AD1: Notes | AE1: Transit pts | AF1: Price pts | AG1: Kitchen pts | AH1: Beds pts | AI1: SCORE | AJ1: Outreach status | AK1: Last checked
A2: =RANK(AI2,$AI$2:$AI$70) -> 38 | B2: Moxy Oakland — receiver-held, built 2021 | C2: 2225 Telegraph Ave, Uptown Oakland | D2: Uptown Oakland | E2: East Bay | F2: 45 | G2: est. by neighborhood (geocode in portal) | H2: tourist-hotel | I2: 172 | J2: 1 | K2: =IF(I2="","",I2*J2) -> 172 | L2: 1000 | M2: 1400 | N2: =IF(L2="","",ROUND((L2+M2)/2/J2,0)) -> 1200 | O2: =IF(N2="","",N2*Weights!$B$12) -> 54000 | P2: none | Q2: receivership | R2: Jewel | S2: expansion | T2: no | W2: Receiver collecting $0 — pitch $1,000–1,400/room | X2: Approach receiver Michelle Russo (HotelAVE) | Y2: Michelle Russo, receiver — HotelAVE; also Acore Capital West Coast asset mgmt | Z2: via hotelave.com | AA2: — | AB2: ⭐ Jewels — call these first | AC2: SF Standard: https://sfstandard.com/2026/01/20/oakland-moxy-hotel-closed/ TRD: https://therealdeal.com/san-francisco/2026/01/21/moxy-hotel-shutters-in-oakland-after-loan-default/ Oaklandside: https://oaklandside.org/2026/01/20/moxy-uptown-oakland-stops-taking-hotel-reservations-and-is-expected-to-close/ | AD2: Re-verified July 16: zero movement since January — no sale motion, no auction. Receiver Michelle Russo (HotelAVE) has a dark, brand-new 172-room building earning $0; a master lease is a receiver's dream. Second door: developer Tidewater Capital still carries a live '2225 Telegraph' page in its listings portfolio (tidewatercap.com/listings/2225-telegraph) — call them too, plus Acore's West Coast asset management. | AE2: =IF(LEFT(E2,2)="SF",IF(F2="",0,Weights!$B$2*MAX(0,MIN(1,(Weights!$B$9-F2)/(Weights!$B$9-Weights!$B$8)))),0) -> 0 | AF2: =IF(N2="",5,Weights!$B$3*MAX(0,MIN(1,(Weights!$B$7-N2)/(Weights!$B$7-Weights!$B$6)))) -> 25 | AG2: =IF(P2="none",0,IF(P2="unknown",5,Weights!$B$4)) -> 0 | AH2: =IF(K2="",4,IF(AND(K2>=Weights!$B$13,K2<=Weights!$B$14),Weights!$B$5,IF(K2>100,15,IF(K2>=20,12,4)))) -> 15 | AI2: =IF(OR(Q2="taken",Q2="sold",Q2="ruled-out"),0,MIN(IF(AND(H2="tourist-hotel",P2="none"),Weights!$B$11,100),AE2+AF2+AG2+AH2)+IF(T2="yes",Weights!$B$10,0)) -> 40 | AJ2: not-contacted | AK2: Jul 16 2026 (report)
A3: =RANK(AI3,$AI$2:$AI$70) -> 11 | B3: Crystal Hotel — 'Residential Master Lease available' | C3: 2766–2770 Mission St (at ~24th), Mission, SF | D3: Mission | E3: SF-other | F3: 32 | G3: est. by neighborhood (geocode in portal) | H3: sro-hotel | I3: 45 | J3: 1 | K3: =IF(I3="","",I3*J3) -> 45 | L3: 500 | M3: 500 | N3: =IF(L3="","",ROUND((L3+M3)/2/J3,0)) -> 500 | O3: =IF(N3="","",N3*Weights!$B$12) -> 22500 | P3: communal | Q3: on-market | R3: Jewel | S3: q1-2027 | T3: unknown | W3: $5.5M ask ($122k/room) · listed 2.5 YEARS = highly negotiable | X3: Call broker Richard Ehmer, (415) 225-5176 · rehmer@ehmergroup.com | Y3: Richard Ehmer — The Ehmer Group | Z3: (415) 225-5176 | AA3: rehmer@ehmergroup.com | AB3: ⭐ Jewels — call these first | AC3: LoopNet listing: https://www.loopnet.com/Listing/2766-2770-Mission-St-San-Francisco-CA/30746850/ Showcase: https://www.showcase.com/2766-2770-mission-st-san-francisco-ca-94110/30746850/ | AD3: Published master-lease terms $500/room = $22,500/mo for all 45 rooms. Only 31/45 rooms permitted — pull Chapter 41 split from DBI. | CONFIRMED master-lease terms on the Realmo mirror: $500/room/month = $22,500/mo for the WHOLE 45-room building — less than half the low end of budget, and rooms at this exact building retail at $1,575/mo all-in (a 3x spread). $450k of recent cap-ex incl. soft-story seismic. Diligence flags: only 31 of 45 rooms are permitted; pull the Chapter 41 residential/tourist split from DBI; 24th & Mission street conditions are improving under 2026 police surge but still rough. Someone already branded it 'Crystal Startup Hotel' once — the concept fits. | AE3: =IF(LEFT(E3,2)="SF",IF(F3="",0,Weights!$B$2*MAX(0,MIN(1,(Weights!$B$9-F3)/(Weights!$B$9-Weights!$B$8)))),0) -> 13 | AF3: =IF(N3="",5,Weights!$B$3*MAX(0,MIN(1,(Weights!$B$7-N3)/(Weights!$B$7-Weights!$B$6)))) -> 30 | AG3: =IF(P3="none",0,IF(P3="unknown",5,Weights!$B$4)) -> 15 | AH3: =IF(K3="",4,IF(AND(K3>=Weights!$B$13,K3<=Weights!$B$14),Weights!$B$5,IF(K3>100,15,IF(K3>=20,12,4)))) -> 20 | AI3: =IF(OR(Q3="taken",Q3="sold",Q3="ruled-out"),0,MIN(IF(AND(H3="tourist-hotel",P3="none"),Weights!$B$11,100),AE3+AF3+AG3+AH3)+IF(T3="yes",Weights!$B$10,0)) -> 78 | AJ3: not-contacted | AK3: Jul 16 2026 (report)
A4: =RANK(AI4,$AI$2:$AI$70) -> 19 | B4: Hill Castle Apartments — 160 units at $43k/unit basis | C4: 1431 Jackson St, Lakeside, Downtown Oakland | D4: Downtown Oakland | E4: East Bay | F4: 40 | G4: est. by neighborhood (geocode in portal) | H4: apartment-block | I4: 160 | J4: 1 | K4: =IF(I4="","",I4*J4) -> 160 | L4: 700 | M4: 1000 | N4: =IF(L4="","",ROUND((L4+M4)/2/J4,0)) -> 850 | O4: =IF(N4="","",N4*Weights!$B$12) -> 38250 | P4: private | Q4: active | R4: Jewel | S4: expansion | T4: yes | W4: Sold Mar 30, 2026 for $6.95M ALL-CASH ('downtown fire sale') | X4: Now run by MAG Management — property office (510) 444-6004 | Y4: MAG Management (property office); buyer via 3/30/26 deed pull, Alameda Co. recorder | Z4: (510) 444-6004 | AA4: hillcastle.gaehwiler.com | AB4: ⭐ Jewels — call these first | AC4: Hoodline, Apr 2026: https://hoodline.com/2026/04/oakland-s-hill-castle-dumps-for-6-95-million-in-downtown-fire-sale/ Building leasing page: https://hillcastle.gaehwiler.com/contactus.aspx | AD4: Deep-dive done: buyer is almost certainly the Gaehwiler family (SF owner-operator; their MAG Management runs the building and it's already on their web platform). Studios $1,250–1,575, 1BRs $1,650–1,875, actively leasing with flex terms = classic lease-up pressure. Blocks from Lake Merritt + 12th St BART, Walk Score 98. Direct-deal family operator: MAG main (415) 550-0300; Lana August, tenancy manager, (415) 720-0820, lana.august@magmanagement.com; property office (510) 444-6004. | AE4: =IF(LEFT(E4,2)="SF",IF(F4="",0,Weights!$B$2*MAX(0,MIN(1,(Weights!$B$9-F4)/(Weights!$B$9-Weights!$B$8)))),0) -> 0 | AF4: =IF(N4="",5,Weights!$B$3*MAX(0,MIN(1,(Weights!$B$7-N4)/(Weights!$B$7-Weights!$B$6)))) -> 30 | AG4: =IF(P4="none",0,IF(P4="unknown",5,Weights!$B$4)) -> 15 | AH4: =IF(K4="",4,IF(AND(K4>=Weights!$B$13,K4<=Weights!$B$14),Weights!$B$5,IF(K4>100,15,IF(K4>=20,12,4)))) -> 15 | AI4: =IF(OR(Q4="taken",Q4="sold",Q4="ruled-out"),0,MIN(IF(AND(H4="tourist-hotel",P4="none"),Weights!$B$11,100),AE4+AF4+AG4+AH4)+IF(T4="yes",Weights!$B$10,0)) -> 65 | AJ4: not-contacted | AK4: Jul 16 2026 (report)
A5: =RANK(AI5,$AI$2:$AI$70) -> 38 | B5: Embassy Hotel — 84 rooms, on-market, unencumbered | C5: 610 Polk St (at Turk), Van Ness corridor, SF | D5: Civic Center | E5: SF-priority | F5: 14 | G5: est. by neighborhood (geocode in portal) | H5: tourist-hotel | I5: 84 | J5: 1 | K5: =IF(I5="","",I5*J5) -> 84 | L5: 1100 | M5: 1300 | N5: =IF(L5="","",ROUND((L5+M5)/2/J5,0)) -> 1200 | O5: =IF(N5="","",N5*Weights!$B$12) -> 54000 | P5: none | Q5: on-market | R5: Jewel | S5: q1-2027;expansion | T5: no | W5: For sale via CBRE Hotels; rack rate $55–64/night = struggling | X5: CBRE Hotels listing team; lowball buy or master lease to owner | Y5: CBRE Hotels — SF listing team (ask for 610 Polk St) | Z5: CBRE SF (415) 772-0123 — verify | AA5: cbre.com/properties | AB5: Report §6e | AC5: Hotel News Resource — CBRE listing: https://www.hotelnewsresource.com/article131697.html Hotel site: https://www.theembassyhotelsf.com/ | AD5: The best size/location/price fit found in round 5: fee simple, no brand, no management contract, non-union — nothing standing between the owner and a master lease. At $55/night rack the hotel grosses ~$1,400/room/month at FULL occupancy; a guaranteed $1,100–1,300/room master lease beats their reality. | AE5: =IF(LEFT(E5,2)="SF",IF(F5="",0,Weights!$B$2*MAX(0,MIN(1,(Weights!$B$9-F5)/(Weights!$B$9-Weights!$B$8)))),0) -> 31 | AF5: =IF(N5="",5,Weights!$B$3*MAX(0,MIN(1,(Weights!$B$7-N5)/(Weights!$B$7-Weights!$B$6)))) -> 25 | AG5: =IF(P5="none",0,IF(P5="unknown",5,Weights!$B$4)) -> 0 | AH5: =IF(K5="",4,IF(AND(K5>=Weights!$B$13,K5<=Weights!$B$14),Weights!$B$5,IF(K5>100,15,IF(K5>=20,12,4)))) -> 12 | AI5: =IF(OR(Q5="taken",Q5="sold",Q5="ruled-out"),0,MIN(IF(AND(H5="tourist-hotel",P5="none"),Weights!$B$11,100),AE5+AF5+AG5+AH5)+IF(T5="yes",Weights!$B$10,0)) -> 40 | AJ5: not-contacted | AK5: Jul 16 2026 (report)
A6: =RANK(AI6,$AI$2:$AI$70) -> 38 | B6: Hotel Union Square — 131 rooms, dark since 2021 | C6: 114–120 Powell St, Union Square, SF | D6: Union Square | E6: SF-priority | F6: 8 | G6: est. by neighborhood (geocode in portal) | H6: tourist-hotel | I6: 131 | J6: 1 | K6: =IF(I6="","",I6*J6) -> 131 | L6: 1500 | M6: 2000 | N6: =IF(L6="","",ROUND((L6+M6)/2/J6,0)) -> 1750 | O6: =IF(N6="","",N6*Weights!$B$12) -> 78750 | P6: none | Q6: dark | R6: Jewel | S6: q1-2027;expansion | T6: no | W6: New owner paid ~$30M vs $102M debt wiped | X6: Catch owner before he commits to hotel use | Y6: Owner Mahmood Alam (Faizan Corp, Ukiah) | Z6: (510) 862-3333 (per 2023 CEQA filing) | AA6: alam786@aol.com ⚠ · CA SoS lookup: "Hotel Union Square LLC" | AB6: ⭐ Jewels — call these first | AC6: SF Standard: https://sfstandard.com/2025/09/26/shuttered-union-square-hotel-finds-new-buyer/ | AD6: Shuttered ~5 years; sold Sept 2025 to investor Mahmood Alam at ~$229k/key with no announced plan. A low-basis owner holding a dark building = ideal master-lease counterparty. 131 genuinely nice rooms covers 60 people twice over; target $1,500–2,000/room. | AE6: =IF(LEFT(E6,2)="SF",IF(F6="",0,Weights!$B$2*MAX(0,MIN(1,(Weights!$B$9-F6)/(Weights!$B$9-Weights!$B$8)))),0) -> 35 | AF6: =IF(N6="",5,Weights!$B$3*MAX(0,MIN(1,(Weights!$B$7-N6)/(Weights!$B$7-Weights!$B$6)))) -> 11.25 | AG6: =IF(P6="none",0,IF(P6="unknown",5,Weights!$B$4)) -> 0 | AH6: =IF(K6="",4,IF(AND(K6>=Weights!$B$13,K6<=Weights!$B$14),Weights!$B$5,IF(K6>100,15,IF(K6>=20,12,4)))) -> 15 | AI6: =IF(OR(Q6="taken",Q6="sold",Q6="ruled-out"),0,MIN(IF(AND(H6="tourist-hotel",P6="none"),Weights!$B$11,100),AE6+AF6+AG6+AH6)+IF(T6="yes",Weights!$B$10,0)) -> 40 | AJ6: not-contacted | AK6: Jul 16 2026 (report)
A7: =RANK(AI7,$AI$2:$AI$70) -> 10 | B7: AAU dorm — 736 Jones St | C7: 736 Jones St, Nob Hill, SF | D7: Nob Hill | E7: SF-priority | F7: 18 | G7: est. by neighborhood (geocode in portal) | H7: dorm | I7: 36 | J7: 2 | K7: =IF(I7="","",I7*J7) -> 72 | L7: 1100 | M7: 1500 | N7: =IF(L7="","",ROUND((L7+M7)/2/J7,0)) -> 650 | O7: =IF(N7="","",N7*Weights!$B$12) -> 29250 | P7: communal | Q7: dark | R7: Jewel | S7: bridge-sept;q1-2027;femme-house | T7: unknown | U7: yes | W7: 1055 Pine asks $20M; leases negotiable | X7: One motivated seller — M&M brokers | Y7: AAU Housing Office — existing landlord, warm intro | Z7: via 79 New Montgomery switchboard | AA7: academyart.edu/campus-athletics/housing | AB7: ⭐ Jewels — call these first | AC7: TRD — $130M portfolio: https://therealdeal.com/san-francisco/2025/10/22/san-francisco-art-academy-to-sell-130-million-portfolio/ 1055 Pine LoopNet: https://www.loopnet.com/Listing/1055-Pine-St-San-Francisco-CA/38157856/ AAU housing page: https://www.academyart.edu/campus-athletics/housing/ 736 Jones: https://www.apartments.com/academy-of-art-university-san-francisco-ca/s6esxj6/ | AD7: Round-4 check: none of the dorms is formally listed — the $130M portfolio never included them (its residential pieces, 1055 Pine and 1946 Van Ness, are under contract). AAU's facilities page still shows all four as student housing, though 736 Jones and 860 Sutter were dropped from the current-housing page — mixed signals that only a direct ask resolves. Two routes: the existing landlord relationship, and Marcus & Millichap (handling ALL AAU dispositions) for an off-market approach. Comp: the Commodore dorm-hotel traded at ~$13M (~$115k/key). | AE7: =IF(LEFT(E7,2)="SF",IF(F7="",0,Weights!$B$2*MAX(0,MIN(1,(Weights!$B$9-F7)/(Weights!$B$9-Weights!$B$8)))),0) -> 27 | AF7: =IF(N7="",5,Weights!$B$3*MAX(0,MIN(1,(Weights!$B$7-N7)/(Weights!$B$7-Weights!$B$6)))) -> 30 | AG7: =IF(P7="none",0,IF(P7="unknown",5,Weights!$B$4)) -> 15 | AH7: =IF(K7="",4,IF(AND(K7>=Weights!$B$13,K7<=Weights!$B$14),Weights!$B$5,IF(K7>100,15,IF(K7>=20,12,4)))) -> 12 | AI7: =IF(OR(Q7="taken",Q7="sold",Q7="ruled-out"),0,MIN(IF(AND(H7="tourist-hotel",P7="none"),Weights!$B$11,100),AE7+AF7+AG7+AH7)+IF(T7="yes",Weights!$B$10,0)) -> 84 | AJ7: not-contacted | AK7: Jul 16 2026 (report)
A8: =RANK(AI8,$AI$2:$AI$70) -> 5 | B8: AAU dorm — 860 Sutter St | C8: 860 Sutter St, Nob Hill, SF | D8: Nob Hill | E8: SF-priority | F8: 16 | G8: est. by neighborhood (geocode in portal) | H8: dorm | I8: 60 | J8: 2 | K8: =IF(I8="","",I8*J8) -> 120 | L8: 1100 | M8: 1500 | N8: =IF(L8="","",ROUND((L8+M8)/2/J8,0)) -> 650 | O8: =IF(N8="","",N8*Weights!$B$12) -> 29250 | P8: communal | Q8: dark | R8: Jewel | S8: bridge-sept;q1-2027;expansion | T8: unknown | U8: yes | W8: 1055 Pine asks $20M; leases negotiable | X8: One motivated seller — M&M brokers | Y8: AAU Housing Office — existing landlord, warm intro | Z8: via 79 New Montgomery switchboard | AA8: academyart.edu/campus-athletics/housing | AB8: ⭐ Jewels — call these first | AC8: TRD — $130M portfolio: https://therealdeal.com/san-francisco/2025/10/22/san-francisco-art-academy-to-sell-130-million-portfolio/ 1055 Pine LoopNet: https://www.loopnet.com/Listing/1055-Pine-St-San-Francisco-CA/38157856/ AAU housing page: https://www.academyart.edu/campus-athletics/housing/ 736 Jones: https://www.apartments.com/academy-of-art-university-san-francisco-ca/s6esxj6/ | AD8: Round-4 check: none of the dorms is formally listed — the $130M portfolio never included them (its residential pieces, 1055 Pine and 1946 Van Ness, are under contract). AAU's facilities page still shows all four as student housing, though 736 Jones and 860 Sutter were dropped from the current-housing page — mixed signals that only a direct ask resolves. Two routes: the existing landlord relationship, and Marcus & Millichap (handling ALL AAU dispositions) for an off-market approach. Comp: the Commodore dorm-hotel traded at ~$13M (~$115k/key). | AE8: =IF(LEFT(E8,2)="SF",IF(F8="",0,Weights!$B$2*MAX(0,MIN(1,(Weights!$B$9-F8)/(Weights!$B$9-Weights!$B$8)))),0) -> 29 | AF8: =IF(N8="",5,Weights!$B$3*MAX(0,MIN(1,(Weights!$B$7-N8)/(Weights!$B$7-Weights!$B$6)))) -> 30 | AG8: =IF(P8="none",0,IF(P8="unknown",5,Weights!$B$4)) -> 15 | AH8: =IF(K8="",4,IF(AND(K8>=Weights!$B$13,K8<=Weights!$B$14),Weights!$B$5,IF(K8>100,15,IF(K8>=20,12,4)))) -> 15 | AI8: =IF(OR(Q8="taken",Q8="sold",Q8="ruled-out"),0,MIN(IF(AND(H8="tourist-hotel",P8="none"),Weights!$B$11,100),AE8+AF8+AG8+AH8)+IF(T8="yes",Weights!$B$10,0)) -> 89 | AJ8: not-contacted | AK8: Jul 16 2026 (report)
A9: =RANK(AI9,$AI$2:$AI$70) -> 7 | B9: AAU dorm — 1080 Bush St | C9: 1080 Bush St, Nob Hill, SF | D9: Nob Hill | E9: SF-priority | F9: 17 | G9: est. by neighborhood (geocode in portal) | H9: dorm | I9: 57 | J9: 2 | K9: =IF(I9="","",I9*J9) -> 114 | L9: 1100 | M9: 1500 | N9: =IF(L9="","",ROUND((L9+M9)/2/J9,0)) -> 650 | O9: =IF(N9="","",N9*Weights!$B$12) -> 29250 | P9: communal | Q9: active | R9: Jewel | S9: q1-2027;expansion | T9: unknown | U9: yes | W9: 1055 Pine asks $20M; leases negotiable | X9: One motivated seller — M&M brokers | Y9: AAU Housing Office — existing landlord, warm intro | Z9: via 79 New Montgomery switchboard | AA9: academyart.edu/campus-athletics/housing | AB9: ⭐ Jewels — call these first | AC9: TRD — $130M portfolio: https://therealdeal.com/san-francisco/2025/10/22/san-francisco-art-academy-to-sell-130-million-portfolio/ 1055 Pine LoopNet: https://www.loopnet.com/Listing/1055-Pine-St-San-Francisco-CA/38157856/ AAU housing page: https://www.academyart.edu/campus-athletics/housing/ 736 Jones: https://www.apartments.com/academy-of-art-university-san-francisco-ca/s6esxj6/ | AD9: Round-4 check: none of the dorms is formally listed — the $130M portfolio never included them (its residential pieces, 1055 Pine and 1946 Van Ness, are under contract). AAU's facilities page still shows all four as student housing, though 736 Jones and 860 Sutter were dropped from the current-housing page — mixed signals that only a direct ask resolves. Two routes: the existing landlord relationship, and Marcus & Millichap (handling ALL AAU dispositions) for an off-market approach. Comp: the Commodore dorm-hotel traded at ~$13M (~$115k/key). | AE9: =IF(LEFT(E9,2)="SF",IF(F9="",0,Weights!$B$2*MAX(0,MIN(1,(Weights!$B$9-F9)/(Weights!$B$9-Weights!$B$8)))),0) -> 28 | AF9: =IF(N9="",5,Weights!$B$3*MAX(0,MIN(1,(Weights!$B$7-N9)/(Weights!$B$7-Weights!$B$6)))) -> 30 | AG9: =IF(P9="none",0,IF(P9="unknown",5,Weights!$B$4)) -> 15 | AH9: =IF(K9="",4,IF(AND(K9>=Weights!$B$13,K9<=Weights!$B$14),Weights!$B$5,IF(K9>100,15,IF(K9>=20,12,4)))) -> 15 | AI9: =IF(OR(Q9="taken",Q9="sold",Q9="ruled-out"),0,MIN(IF(AND(H9="tourist-hotel",P9="none"),Weights!$B$11,100),AE9+AF9+AG9+AH9)+IF(T9="yes",Weights!$B$10,0)) -> 88 | AJ9: not-contacted | AK9: Jul 16 2026 (report)
A10: =RANK(AI10,$AI$2:$AI$70) -> 7 | B10: AAU dorm — 680 Sutter St | C10: 680 Sutter St, Nob Hill, SF | D10: Nob Hill | E10: SF-priority | F10: 14 | G10: est. by neighborhood (geocode in portal) | H10: dorm | I10: 50 | J10: 2 | K10: =IF(I10="","",I10*J10) -> 100 | L10: 1100 | M10: 1500 | N10: =IF(L10="","",ROUND((L10+M10)/2/J10,0)) -> 650 | O10: =IF(N10="","",N10*Weights!$B$12) -> 29250 | P10: communal | Q10: active | R10: Jewel | S10: q1-2027 | T10: unknown | U10: yes | W10: 1055 Pine asks $20M; leases negotiable | X10: One motivated seller — M&M brokers | Y10: AAU Housing Office — existing landlord, warm intro | Z10: via 79 New Montgomery switchboard | AA10: academyart.edu/campus-athletics/housing | AB10: ⭐ Jewels — call these first | AC10: TRD — $130M portfolio: https://therealdeal.com/san-francisco/2025/10/22/san-francisco-art-academy-to-sell-130-million-portfolio/ 1055 Pine LoopNet: https://www.loopnet.com/Listing/1055-Pine-St-San-Francisco-CA/38157856/ AAU housing page: https://www.academyart.edu/campus-athletics/housing/ 736 Jones: https://www.apartments.com/academy-of-art-university-san-francisco-ca/s6esxj6/ | AD10: Round-4 check: none of the dorms is formally listed — the $130M portfolio never included them (its residential pieces, 1055 Pine and 1946 Van Ness, are under contract). AAU's facilities page still shows all four as student housing, though 736 Jones and 860 Sutter were dropped from the current-housing page — mixed signals that only a direct ask resolves. Two routes: the existing landlord relationship, and Marcus & Millichap (handling ALL AAU dispositions) for an off-market approach. Comp: the Commodore dorm-hotel traded at ~$13M (~$115k/key). | AE10: =IF(LEFT(E10,2)="SF",IF(F10="",0,Weights!$B$2*MAX(0,MIN(1,(Weights!$B$9-F10)/(Weights!$B$9-Weights!$B$8)))),0) -> 31 | AF10: =IF(N10="",5,Weights!$B$3*MAX(0,MIN(1,(Weights!$B$7-N10)/(Weights!$B$7-Weights!$B$6)))) -> 30 | AG10: =IF(P10="none",0,IF(P10="unknown",5,Weights!$B$4)) -> 15 | AH10: =IF(K10="",4,IF(AND(K10>=Weights!$B$13,K10<=Weights!$B$14),Weights!$B$5,IF(K10>100,15,IF(K10>=20,12,4)))) -> 12 | AI10: =IF(OR(Q10="taken",Q10="sold",Q10="ruled-out"),0,MIN(IF(AND(H10="tourist-hotel",P10="none"),Weights!$B$11,100),AE10+AF10+AG10+AH10)+IF(T10="yes",Weights!$B$10,0)) -> 88 | AJ10: not-contacted | AK10: Jul 16 2026 (report)
A11: =RANK(AI11,$AI$2:$AI$70) -> 55 | B11: Waterfront Hotel — closed, actively brokered | C11: 10 Washington St, Jack London Square, Oakland | D11: Jack London Sq, Oakland | E11: East Bay | F11: 55 | G11: est. by neighborhood (geocode in portal) | H11: tourist-hotel | I11: 145 | J11: 1 | K11: =IF(I11="","",I11*J11) -> 145 | L11: 1200 | M11: 1800 | N11: =IF(L11="","",ROUND((L11+M11)/2/J11,0)) -> 1500 | O11: =IF(N11="","",N11*Weights!$B$12) -> 67500 | P11: none | Q11: dark | R11: Jewel | S11: expansion | T11: no | W11: Leasehold, 'fully unencumbered' — unsold a year+ | X11: Call Berkadia (Kelso / Michels) | Y11: Jared Kelso / Steve Michels — Berkadia | Z11: 646-432-7480 / 646-432-7475 | AA11: Port of Oakland + CIM consent needed | AB11: ⭐ Jewels — call these first | AC11: Berkadia listing: https://properties.berkadia.com/waterfront-hotel-414425/ CBS — closure: https://www.cbsnews.com/sanfrancisco/news/oakland-landmark-waterfront-hotel-jack-london-square-closes/ | AD11: Verified July 2026: still unsold after 18 months, no price guidance — a stuck listing. Contacts: Jared Kelso 646-432-7480 / Steve Michels 646-432-7475 (Berkadia). Caveat: leasehold — land is Port of Oakland, ground lease runs through CIM Group, so Port consent likely needed. Comp: Homewood Suites Oakland just sold at $42k/key. | AE11: =IF(LEFT(E11,2)="SF",IF(F11="",0,Weights!$B$2*MAX(0,MIN(1,(Weights!$B$9-F11)/(Weights!$B$9-Weights!$B$8)))),0) -> 0 | AF11: =IF(N11="",5,Weights!$B$3*MAX(0,MIN(1,(Weights!$B$7-N11)/(Weights!$B$7-Weights!$B$6)))) -> 17.5 | AG11: =IF(P11="none",0,IF(P11="unknown",5,Weights!$B$4)) -> 0 | AH11: =IF(K11="",4,IF(AND(K11>=Weights!$B$13,K11<=Weights!$B$14),Weights!$B$5,IF(K11>100,15,IF(K11>=20,12,4)))) -> 15 | AI11: =IF(OR(Q11="taken",Q11="sold",Q11="ruled-out"),0,MIN(IF(AND(H11="tourist-hotel",P11="none"),Weights!$B$11,100),AE11+AF11+AG11+AH11)+IF(T11="yes",Weights!$B$10,0)) -> 32.5 | AJ11: not-contacted | AK11: Jul 16 2026 (report)
A12: =RANK(AI12,$AI$2:$AI$70) -> 26 | B12: 1900 Broadway co-living block (verified pricing) | C12: Uptown Oakland, on top of 19th St BART | D12: Uptown Oakland | E12: East Bay | F12: 40 | G12: est. by neighborhood (geocode in portal) | H12: co-living | I12: 60 | J12: 1 | K12: =IF(I12="","",I12*J12) -> 60 | L12: 1400 | M12: 1660 | N12: =IF(L12="","",ROUND((L12+M12)/2/J12,0)) -> 1530 | O12: =IF(N12="","",N12*Weights!$B$12) -> 68850 | P12: private | Q12: active | R12: Jewel | S12: bridge-sept;expansion | T12: yes | W12: $1,803/bed listed · 4 wks free → ~$1,660 effective · block deal ≈ $1,400–1,550 | X12: Negotiate 40–60 bed block | Y12: Leasing (Bozzuto) · STAK · owner: Behring Companies (Colin Behring) | Z12: 844-932-4196 · (510) 925-4860 | AA12: live1900.com · stakspace.com | AB12: ⭐ Jewels — call these first | AC12: Apartments.com: https://www.apartments.com/1900-broadway-oakland-ca/bht2eec/ live1900.com: https://www.live1900.com/ Zillow — 23 units: https://www.zillow.com/apartments/oakland-ca/1900-broadway/Ch7XFs/ | AD12: Verified live: co-living beds from $1,803 with 4 weeks free; ~23 units on Zillow = leverage. STAK sells Bronze/Silver/Gold apartment+coworking packages ('up to $60k/yr savings') — the group-block product exists in all but name. For 40–60 beds, go over the leasing office (844-932-4196) to owner Behring Companies (Colin Behring). | AE12: =IF(LEFT(E12,2)="SF",IF(F12="",0,Weights!$B$2*MAX(0,MIN(1,(Weights!$B$9-F12)/(Weights!$B$9-Weights!$B$8)))),0) -> 0 | AF12: =IF(N12="",5,Weights!$B$3*MAX(0,MIN(1,(Weights!$B$7-N12)/(Weights!$B$7-Weights!$B$6)))) -> 16.75 | AG12: =IF(P12="none",0,IF(P12="unknown",5,Weights!$B$4)) -> 15 | AH12: =IF(K12="",4,IF(AND(K12>=Weights!$B$13,K12<=Weights!$B$14),Weights!$B$5,IF(K12>100,15,IF(K12>=20,12,4)))) -> 20 | AI12: =IF(OR(Q12="taken",Q12="sold",Q12="ruled-out"),0,MIN(IF(AND(H12="tourist-hotel",P12="none"),Weights!$B$11,100),AE12+AF12+AG12+AH12)+IF(T12="yes",Weights!$B$10,0)) -> 56.75 | AJ12: not-contacted | AK12: Jul 16 2026 (report)
A13: =RANK(AI13,$AI$2:$AI$70) -> 29 | B13: Ora Apartments — REO, on market now | C13: 1815 Alice St, Downtown Oakland | D13: Downtown Oakland | E13: East Bay | F13: 45 | G13: est. by neighborhood (geocode in portal) | H13: apartment-block | I13: 74 | J13: 2 | K13: =IF(I13="","",I13*J13) -> 148 | L13: 2200 | M13: 2800 | N13: =IF(L13="","",ROUND((L13+M13)/2/J13,0)) -> 1250 | O13: =IF(N13="","",N13*Weights!$B$12) -> 56250 | P13: private | Q13: on-market | R13: Bargain / distressed | S13: expansion | T13: no | W13: Lender foreclosed at $25M vs $41M (2021); JLL listing | X13: Master lease or bulk-unit deal with lender-seller | Y13: JLL: Ryan Wagner · Matt Kroger · Brandon Geraldo · Fatai Alashe | Z13: (415) 706-7215 · (415) 395-7219 · (415) 395-7273 · (415) 395-7284 | AA13: firstname.lastname@jll.com | AB13: Bargains / distressed | AC13: TRD, May 2026: https://therealdeal.com/sanfrancisco/2026/05/08/ora-apartments-in-oakland-hit-market-after-foreclosure/ | AD13: Nearly-new building marketed 'below replacement cost.' A credit master tenant filling 74 units is exactly what a lender-seller wants while waiting for a sale. | AE13: =IF(LEFT(E13,2)="SF",IF(F13="",0,Weights!$B$2*MAX(0,MIN(1,(Weights!$B$9-F13)/(Weights!$B$9-Weights!$B$8)))),0) -> 0 | AF13: =IF(N13="",5,Weights!$B$3*MAX(0,MIN(1,(Weights!$B$7-N13)/(Weights!$B$7-Weights!$B$6)))) -> 23.75 | AG13: =IF(P13="none",0,IF(P13="unknown",5,Weights!$B$4)) -> 15 | AH13: =IF(K13="",4,IF(AND(K13>=Weights!$B$13,K13<=Weights!$B$14),Weights!$B$5,IF(K13>100,15,IF(K13>=20,12,4)))) -> 15 | AI13: =IF(OR(Q13="taken",Q13="sold",Q13="ruled-out"),0,MIN(IF(AND(H13="tourist-hotel",P13="none"),Weights!$B$11,100),AE13+AF13+AG13+AH13)+IF(T13="yes",Weights!$B$10,0)) -> 53.75 | AJ13: not-contacted | AK13: Jul 16 2026 (report)
A14: =RANK(AI14,$AI$2:$AI$70) -> 31 | B14: Moran + Telegraph Arts — one lender, 175 units | C14: 570 21st St + 471 26th St, Uptown Oakland (0.4 mi apart) | D14: Uptown Oakland | E14: East Bay | F14: 45 | G14: est. by neighborhood (geocode in portal) | H14: apartment-block | I14: 175 | J14: 2 | K14: =IF(I14="","",I14*J14) -> 350 | L14: 2200 | M14: 3000 | N14: =IF(L14="","",ROUND((L14+M14)/2/J14,0)) -> 1300 | O14: =IF(N14="","",N14*Weights!$B$12) -> 58500 | P14: private | Q14: receivership | R14: Bargain / distressed | S14: expansion | T14: no | W14: CWCapital took both ~50% below assessed (2026) | X14: One special-servicer negotiation covers everything | Y14: CWCapital Asset Management | Z14: (202) 715-9500 | AA14: sells via RealINSIGHT Marketplace (800) 915-7015 | AB14: Bargains / distressed | AC14: Multifamily Dive: https://www.multifamilydive.com/news/oakland-multifamily-distress-auction-loan-default/814338/ TRD: https://therealdeal.com/sanfrancisco/2026/04/09/lender-forecloses-on-two-oakland-apartment-complexes/ Hoodline: https://hoodline.com/2026/03/foreclosure-shock-rocks-uptown-oakland-as-two-apartment-hubs-teeter/ | AD14: Both foreclosed spring 2026. A single counterparty controlling two nearby modern buildings = the whole program (and its expansion) in one deal, at distressed pricing. Also the strongest 'pair' on the board. | AE14: =IF(LEFT(E14,2)="SF",IF(F14="",0,Weights!$B$2*MAX(0,MIN(1,(Weights!$B$9-F14)/(Weights!$B$9-Weights!$B$8)))),0) -> 0 | AF14: =IF(N14="",5,Weights!$B$3*MAX(0,MIN(1,(Weights!$B$7-N14)/(Weights!$B$7-Weights!$B$6)))) -> 22.5 | AG14: =IF(P14="none",0,IF(P14="unknown",5,Weights!$B$4)) -> 15 | AH14: =IF(K14="",4,IF(AND(K14>=Weights!$B$13,K14<=Weights!$B$14),Weights!$B$5,IF(K14>100,15,IF(K14>=20,12,4)))) -> 15 | AI14: =IF(OR(Q14="taken",Q14="sold",Q14="ruled-out"),0,MIN(IF(AND(H14="tourist-hotel",P14="none"),Weights!$B$11,100),AE14+AF14+AG14+AH14)+IF(T14="yes",Weights!$B$10,0)) -> 52.5 | AJ14: not-contacted | AK14: Jul 16 2026 (report)
A15: =RANK(AI15,$AI$2:$AI$70) -> 68 | B15: 1919 Market St — foreclosed new-build co-living | C15: West Oakland (former Greyhound terminal site) | D15: West Oakland | E15: East Bay | F15: 40 | G15: est. by neighborhood (geocode in portal) | H15: co-living | I15: 102 | J15: 1 | K15: =IF(I15="","",I15*J15) -> 102 | L15: 1300 | M15: 1800 | N15: =IF(L15="","",ROUND((L15+M15)/2/J15,0)) -> 1550 | O15: =IF(N15="","",N15*Weights!$B$12) -> 69750 | P15: communal | Q15: sold | R15: Bargain / distressed | T15: no | W15: Parkview bought at foreclosure for $37.5M (Jan 2026) vs $58.5M debt | X15: Pitch new low-basis owner | AC15: TRD: https://therealdeal.com/sanfrancisco/2026/01/16/west-oakland-apartments-sell-at-foreclosure/ Multifamily Dive: https://www.multifamilydive.com/news/oakland-apartment-foreclosure-multifamily-distress/810263/ | AD15: Newly built by oWow with co-living-style layouts — unusually well suited to 40–60 beds. Owner at a 36% haircut basis needs income. | AE15: =IF(LEFT(E15,2)="SF",IF(F15="",0,Weights!$B$2*MAX(0,MIN(1,(Weights!$B$9-F15)/(Weights!$B$9-Weights!$B$8)))),0) -> 0 | AF15: =IF(N15="",5,Weights!$B$3*MAX(0,MIN(1,(Weights!$B$7-N15)/(Weights!$B$7-Weights!$B$6)))) -> 16.25 | AG15: =IF(P15="none",0,IF(P15="unknown",5,Weights!$B$4)) -> 15 | AH15: =IF(K15="",4,IF(AND(K15>=Weights!$B$13,K15<=Weights!$B$14),Weights!$B$5,IF(K15>100,15,IF(K15>=20,12,4)))) -> 15 | AI15: =IF(OR(Q15="taken",Q15="sold",Q15="ruled-out"),0,MIN(IF(AND(H15="tourist-hotel",P15="none"),Weights!$B$11,100),AE15+AF15+AG15+AH15)+IF(T15="yes",Weights!$B$10,0)) -> 0 | AJ15: not-contacted | AK15: Jul 16 2026 (report)
A16: =RANK(AI16,$AI$2:$AI$70) -> 49 | B16: AC Hotel / Residence Inn Oakland — lender-seized, 1 yr old | C16: 1431 Jefferson St, Downtown Oakland | D16: Downtown Oakland | E16: East Bay | F16: 45 | G16: est. by neighborhood (geocode in portal) | H16: tourist-hotel | I16: 276 | J16: 1 | K16: =IF(I16="","",I16*J16) -> 276 | L16: 1500 | M16: 2200 | N16: =IF(L16="","",ROUND((L16+M16)/2/J16,0)) -> 1850 | O16: =IF(N16="","",N16*Weights!$B$12) -> 83250 | P16: private | Q16: receivership | R16: Bargain / distressed | S16: expansion | T16: no | W16: Defaulted on $101M one year after opening; seized Apr 2025 | X16: Approach the lender | AC16: SF Standard: https://sfstandard.com/2026/01/20/oakland-moxy-hotel-closed/ TRD: https://therealdeal.com/sanfrancisco/2025/07/10/oakland-marriott-city-center-finds-buyer-at-foreclosure/ | AD16: Brand-new extended-stay product (kitchens!) under lender control — arguably the best hotel-side target in Oakland for quality per dollar. | AE16: =IF(LEFT(E16,2)="SF",IF(F16="",0,Weights!$B$2*MAX(0,MIN(1,(Weights!$B$9-F16)/(Weights!$B$9-Weights!$B$8)))),0) -> 0 | AF16: =IF(N16="",5,Weights!$B$3*MAX(0,MIN(1,(Weights!$B$7-N16)/(Weights!$B$7-Weights!$B$6)))) -> 8.75 | AG16: =IF(P16="none",0,IF(P16="unknown",5,Weights!$B$4)) -> 15 | AH16: =IF(K16="",4,IF(AND(K16>=Weights!$B$13,K16<=Weights!$B$14),Weights!$B$5,IF(K16>100,15,IF(K16>=20,12,4)))) -> 15 | AI16: =IF(OR(Q16="taken",Q16="sold",Q16="ruled-out"),0,MIN(IF(AND(H16="tourist-hotel",P16="none"),Weights!$B$11,100),AE16+AF16+AG16+AH16)+IF(T16="yes",Weights!$B$10,0)) -> 38.75 | AJ16: not-contacted | AK16: Jul 16 2026 (report)
A17: =RANK(AI17,$AI$2:$AI$70) -> 55 | B17: Courtyard Oakland Downtown — owner will take any exit | C17: 988 Broadway, Oakland (Chinatown edge) | D17: Downtown Oakland | E17: East Bay | F17: 45 | G17: est. by neighborhood (geocode in portal) | H17: tourist-hotel | I17: 160 | J17: 1 | K17: =IF(I17="","",I17*J17) -> 160 | L17: 1200 | M17: 1800 | N17: =IF(L17="","",ROUND((L17+M17)/2/J17,0)) -> 1500 | O17: =IF(N17="","",N17*Weights!$B$12) -> 67500 | P17: none | Q17: dark | R17: Bargain / distressed | S17: expansion | T17: no | W17: Owner shopped it as a 150-bed shelter, then as 64 apartments | X17: 3–5 yr master lease during entitlement | Y17: Gaw Capital USA, SF office | Z17: (415) 645-7000 | AA17: gawcapitalusa.com contact form | AB17: Bargains / distressed | AC17: TRD, Apr 2026: https://therealdeal.com/san-francisco/2026/04/16/hoteliers-look-to-convert-oakland-marriott-into-apartments/ SF YIMBY: https://sfyimby.com/2026/04/preliminary-application-for-hotel-to-housing-conversion-at-988-broadway-downtown-oakland.html | AD17: Gaw Capital has tried everything with this building (and already lost the Marriott City Center next door to foreclosure). A residential master lease during their apartment-conversion entitlement fits their playbook exactly. | AE17: =IF(LEFT(E17,2)="SF",IF(F17="",0,Weights!$B$2*MAX(0,MIN(1,(Weights!$B$9-F17)/(Weights!$B$9-Weights!$B$8)))),0) -> 0 | AF17: =IF(N17="",5,Weights!$B$3*MAX(0,MIN(1,(Weights!$B$7-N17)/(Weights!$B$7-Weights!$B$6)))) -> 17.5 | AG17: =IF(P17="none",0,IF(P17="unknown",5,Weights!$B$4)) -> 0 | AH17: =IF(K17="",4,IF(AND(K17>=Weights!$B$13,K17<=Weights!$B$14),Weights!$B$5,IF(K17>100,15,IF(K17>=20,12,4)))) -> 15 | AI17: =IF(OR(Q17="taken",Q17="sold",Q17="ruled-out"),0,MIN(IF(AND(H17="tourist-hotel",P17="none"),Weights!$B$11,100),AE17+AF17+AG17+AH17)+IF(T17="yes",Weights!$B$10,0)) -> 32.5 | AJ17: not-contacted | AK17: Jul 16 2026 (report)
A18: =RANK(AI18,$AI$2:$AI$70) -> 38 | B18: Stanford Court — 4-star Nob Hill, receiver in place | C18: 905 California St, Nob Hill, SF | D18: Nob Hill | E18: SF-priority | F18: 20 | G18: est. by neighborhood (geocode in portal) | H18: tourist-hotel | I18: 60 | J18: 1 | K18: =IF(I18="","",I18*J18) -> 60 | L18: 1800 | M18: 2200 | N18: =IF(L18="","",ROUND((L18+M18)/2/J18,0)) -> 2000 | O18: =IF(N18="","",N18*Weights!$B$12) -> 90000 | P18: none | Q18: receivership | R18: Bargain / distressed | S18: q1-2027 | T18: no | W18: $105M default; foreclosure trial July 13, 2026; Eastdil marketing leasehold | X18: Pitch receiver a guaranteed 50–60 room block | Y18: Eastdil Secured SF — ask for the Stanford Court deal team | Z18: (415) 228-2900 | AA18: 101 California St #2950 | AB18: Bargains / distressed | AC18: TRD, Mar 2026: https://therealdeal.com/san-francisco/2026/03/03/nob-hill-hotel-hits-market-again-as-foreclosure-looms/ SFist — case background: https://sfist.com/2025/01/17/nob-hills-posh-stanford-court-hotel-hit-with-foreclosure-lawsuit-over-claims-of-missed-mortgage-payments/ | AD18: Foreclosure trial was held July 13 — no published outcome yet (press lags bench rulings; check the SF Superior Court docket: Deutsche Bank AG v. Pine & Powell Partners). Either way the live counterparties are unchanged: receiver Chad Crandell (CHMWarnick) + Eastdil. A guaranteed 50–60 room block at $1,800–2,200 is 4-star quality — the 'much nicer rooms' winner. | AE18: =IF(LEFT(E18,2)="SF",IF(F18="",0,Weights!$B$2*MAX(0,MIN(1,(Weights!$B$9-F18)/(Weights!$B$9-Weights!$B$8)))),0) -> 25 | AF18: =IF(N18="",5,Weights!$B$3*MAX(0,MIN(1,(Weights!$B$7-N18)/(Weights!$B$7-Weights!$B$6)))) -> 5 | AG18: =IF(P18="none",0,IF(P18="unknown",5,Weights!$B$4)) -> 0 | AH18: =IF(K18="",4,IF(AND(K18>=Weights!$B$13,K18<=Weights!$B$14),Weights!$B$5,IF(K18>100,15,IF(K18>=20,12,4)))) -> 20 | AI18: =IF(OR(Q18="taken",Q18="sold",Q18="ruled-out"),0,MIN(IF(AND(H18="tourist-hotel",P18="none"),Weights!$B$11,100),AE18+AF18+AG18+AH18)+IF(T18="yes",Weights!$B$10,0)) -> 40 | AJ18: not-contacted | AK18: Jul 16 2026 (report)
A19: =RANK(AI19,$AI$2:$AI$70) -> 33 | B19: Parkmerced — bulk units from a receiver | C19: 3711 19th Ave, SF (SW corner, near SFSU) | D19: Parkmerced | E19: SF-other | F19: 50 | G19: est. by neighborhood (geocode in portal) | H19: apartment-block | I19: 60 | J19: 2 | K19: =IF(I19="","",I19*J19) -> 120 | L19: 3000 | M19: 3000 | N19: =IF(L19="","",ROUND((L19+M19)/2/J19,0)) -> 1500 | O19: =IF(N19="","",N19*Weights!$B$12) -> 67500 | P19: private | Q19: receivership | R19: Bargain / distressed | S19: expansion | T19: unknown | W19: In receivership since Mar 2025 ($1.8B default) | X19: 60–120 bed corporate block at a steep discount | Y19: Leasing; receiver = Douglas Wilson Companies | Z19: (415) 689-6252 | AA19: lease@rentbt.com | AB19: Bargains / distressed | AC19: TRD: https://therealdeal.com/san-francisco/2025/03/20/sfs-largest-apartment-complex-ordered-into-receivership/ SF Standard: https://sfstandard.com/2025/04/18/parkmerced-billion-dollar-housing-project-timeline/ | AD19: The fastest 60+ beds in SF at scale: 2–3BR townhomes at 2/room lands near $1,500/bed. Not charming, but September-ready and endlessly scalable. Rent-control structuring needs counsel. | AE19: =IF(LEFT(E19,2)="SF",IF(F19="",0,Weights!$B$2*MAX(0,MIN(1,(Weights!$B$9-F19)/(Weights!$B$9-Weights!$B$8)))),0) -> 0 | AF19: =IF(N19="",5,Weights!$B$3*MAX(0,MIN(1,(Weights!$B$7-N19)/(Weights!$B$7-Weights!$B$6)))) -> 17.5 | AG19: =IF(P19="none",0,IF(P19="unknown",5,Weights!$B$4)) -> 15 | AH19: =IF(K19="",4,IF(AND(K19>=Weights!$B$13,K19<=Weights!$B$14),Weights!$B$5,IF(K19>100,15,IF(K19>=20,12,4)))) -> 15 | AI19: =IF(OR(Q19="taken",Q19="sold",Q19="ruled-out"),0,MIN(IF(AND(H19="tourist-hotel",P19="none"),Weights!$B$11,100),AE19+AF19+AG19+AH19)+IF(T19="yes",Weights!$B$10,0)) -> 47.5 | AJ19: not-contacted | AK19: Jul 16 2026 (report)
A20: =RANK(AI20,$AI$2:$AI$70) -> 6 | B20: Mosser SRO — 1000 Market St (owner stuck) | C20: 1000 Market / Turk St, Mid-Market SF | D20: Civic Center | E20: SF-priority | F20: 3 | G20: est. by neighborhood (geocode in portal) | H20: sro-hotel | I20: 361 | J20: 1 | K20: =IF(I20="","",I20*J20) -> 361 | L20: 1100 | M20: 1400 | N20: =IF(L20="","",ROUND((L20+M20)/2/J20,0)) -> 1250 | O20: =IF(N20="","",N20*Weights!$B$12) -> 56250 | P20: communal | Q20: active | R20: Bargain / distressed | S20: bridge-sept;q1-2027;expansion | T20: unknown | W20: Owner tried converting rooms to tourist use — rejected by Planning (Mar 2025) | X20: Master-lease the rooms he can't fill | Y20: Mosser Companies | Z20: (415) 673-1608 | AA20: mosserliving.com/contact | AB20: Bargains / distressed | AC20: 48 Hills: https://48hills.org/2025/03/planning-commission-rejects-landlord-plan-to-convert-sro-rooms-to-tourist-hotels/ SFADC: https://sfadc.org/2025/03/21/community-victory-planning-commission-rejects-mosser-sro-attempt-to-convert-sro-rooms-to-tourist-hotel/ | AD20: An owner who publicly argued residential SRO doesn't pencil, now stuck with rooms he can't convert. A block lease at $1,100–1,400/room solves his problem and yours. | AE20: =IF(LEFT(E20,2)="SF",IF(F20="",0,Weights!$B$2*MAX(0,MIN(1,(Weights!$B$9-F20)/(Weights!$B$9-Weights!$B$8)))),0) -> 35 | AF20: =IF(N20="",5,Weights!$B$3*MAX(0,MIN(1,(Weights!$B$7-N20)/(Weights!$B$7-Weights!$B$6)))) -> 23.75 | AG20: =IF(P20="none",0,IF(P20="unknown",5,Weights!$B$4)) -> 15 | AH20: =IF(K20="",4,IF(AND(K20>=Weights!$B$13,K20<=Weights!$B$14),Weights!$B$5,IF(K20>100,15,IF(K20>=20,12,4)))) -> 15 | AI20: =IF(OR(Q20="taken",Q20="sold",Q20="ruled-out"),0,MIN(IF(AND(H20="tourist-hotel",P20="none"),Weights!$B$11,100),AE20+AF20+AG20+AH20)+IF(T20="yes",Weights!$B$10,0)) -> 88.75 | AJ20: not-contacted | AK20: Jul 16 2026 (report)
A21: =RANK(AI21,$AI$2:$AI$70) -> 25 | B21: Veritas & Ballast portfolios — bank-controlled SF buildings | C21: Tenderloin / Civic Center / citywide SF | D21: Civic Center | E21: SF-priority | F21: 10 | G21: est. by neighborhood (geocode in portal) | H21: apartment-block | J21: 2 | K21: =IF(I21="","",I21*J21) | N21: =IF(L21="","",ROUND((L21+M21)/2/J21,0)) | O21: =IF(N21="","",N21*Weights!$B$12) | P21: private | Q21: receivership | R21: Bargain / distressed | S21: q1-2027 | T21: unknown | W21: Receiver/lender controlled | X21: Building-level master-lease conversations | Y21: Receiver / lender — identify via SF Assessor-Recorder deed pull | Z21: — | AA21: Prospect Hill Capital (Veritas) / RBC (Ballast) | AB21: Report §6b | AC21: Mission Local: https://missionlocal.org/2025/09/sf-veritas-foreclosure-652-million-debt/ Multifamily Dive — Ballast: https://www.multifamilydive.com/news/goldman-sachs-ballast-investments-distressed-loans-san-francisco/722955/ | AD21: Portfolio play — no single building identified yet; find the receiver/lender contact first. | SF's two mega-distress portfolios. Whoever holds these post-auction inherits scattered vacancy in exactly the neighborhoods with SRO/studio stock. Worth a call to receiver Wald Realty Advisors / Hamilton Zanze. | AE21: =IF(LEFT(E21,2)="SF",IF(F21="",0,Weights!$B$2*MAX(0,MIN(1,(Weights!$B$9-F21)/(Weights!$B$9-Weights!$B$8)))),0) -> 35 | AF21: =IF(N21="",5,Weights!$B$3*MAX(0,MIN(1,(Weights!$B$7-N21)/(Weights!$B$7-Weights!$B$6)))) -> 5 | AG21: =IF(P21="none",0,IF(P21="unknown",5,Weights!$B$4)) -> 15 | AH21: =IF(K21="",4,IF(AND(K21>=Weights!$B$13,K21<=Weights!$B$14),Weights!$B$5,IF(K21>100,15,IF(K21>=20,12,4)))) -> 4 | AI21: =IF(OR(Q21="taken",Q21="sold",Q21="ruled-out"),0,MIN(IF(AND(H21="tourist-hotel",P21="none"),Weights!$B$11,100),AE21+AF21+AG21+AH21)+IF(T21="yes",Weights!$B$10,0)) -> 59 | AJ21: not-contacted | AK21: Jul 16 2026 (report)
A22: =RANK(AI22,$AI$2:$AI$70) -> 58 | B22: St. Anne's Home — closed 6-acre care campus | C22: 300 Lake St, Inner Richmond, SF | D22: Inner Richmond | E22: SF-other | F22: 55 | G22: est. by neighborhood (geocode in portal) | H22: campus | I22: 100 | J22: 1 | K22: =IF(I22="","",I22*J22) -> 100 | N22: =IF(L22="","",ROUND((L22+M22)/2/J22,0)) | O22: =IF(N22="","",N22*Weights!$B$12) | P22: communal | Q22: on-market | R22: Bargain / distressed | S22: q1-2027;expansion | T22: no | W22: Listed $58.5M (May 2025); no closed sale announced | X22: Interim master lease from whoever wins it | Y22: Greg Zielinski — Zielinski Companies (runs the sale for the order) | Z22: (800) 489-2150 / (314) 644-2150 | AA22: mail@zielinskico.com | AB22: Bargains / distressed | AC22: TRD: https://therealdeal.com/san-francisco/2025/05/12/catholic-order-lists-sf-nursing-home-site-for-59-million/ SF Standard: https://sfstandard.com/2025/01/09/st-annes-home-little-sisters-poor-to-close-sf/ | AD22: Closed 2025 after 124 years (Little Sisters of the Poor). Any developer buyer faces a 3–6 year rezoning window — a ~100-bed interim lease of a fully built residential building is very plausible. Chase the winning bidder. | AE22: =IF(LEFT(E22,2)="SF",IF(F22="",0,Weights!$B$2*MAX(0,MIN(1,(Weights!$B$9-F22)/(Weights!$B$9-Weights!$B$8)))),0) -> 0 | AF22: =IF(N22="",5,Weights!$B$3*MAX(0,MIN(1,(Weights!$B$7-N22)/(Weights!$B$7-Weights!$B$6)))) -> 5 | AG22: =IF(P22="none",0,IF(P22="unknown",5,Weights!$B$4)) -> 15 | AH22: =IF(K22="",4,IF(AND(K22>=Weights!$B$13,K22<=Weights!$B$14),Weights!$B$5,IF(K22>100,15,IF(K22>=20,12,4)))) -> 12 | AI22: =IF(OR(Q22="taken",Q22="sold",Q22="ruled-out"),0,MIN(IF(AND(H22="tourist-hotel",P22="none"),Weights!$B$11,100),AE22+AF22+AG22+AH22)+IF(T22="yes",Weights!$B$10,0)) -> 32 | AJ22: not-contacted | AK22: Jul 16 2026 (report)
A23: =RANK(AI23,$AI$2:$AI$70) -> 58 | B23: Santa Sabina Center — closed convent retreat | C23: 25 Magnolia Ave, San Rafael (25–30 min to SF) | D23: San Rafael | E23: North Bay | F23: 90 | G23: est. by neighborhood (geocode in portal) | H23: campus | I23: 38 | J23: 2 | K23: =IF(I23="","",I23*J23) -> 76 | N23: =IF(L23="","",ROUND((L23+M23)/2/J23,0)) | O23: =IF(N23="","",N23*Weights!$B$12) | P23: communal | Q23: on-market | R23: Bargain / distressed | S23: expansion | T23: no | W23: For sale via faith-property specialist; price undisclosed | X23: Mission-aligned lease-to-own pitch | Y23: Dominic Dutra — 3D Strategies | Z23: (510) 366-9931 | AA23: ddutra@3Dstrategies.com | AB23: Bargains / distressed | AC23: Listing background: https://phillipacriswell.com/blog/historic-bay-area-retreat-will-go-for-sale Yelp — closed: https://www.yelp.com/biz/santa-sabina-center-san-rafael | AD23: Dominican Sisters closed it Feb 2026. The buyer pool for convents is tiny — a residential-education story plus lease-to-own could win at a low number. Turnkey: dining hall, library, conference space. | AE23: =IF(LEFT(E23,2)="SF",IF(F23="",0,Weights!$B$2*MAX(0,MIN(1,(Weights!$B$9-F23)/(Weights!$B$9-Weights!$B$8)))),0) -> 0 | AF23: =IF(N23="",5,Weights!$B$3*MAX(0,MIN(1,(Weights!$B$7-N23)/(Weights!$B$7-Weights!$B$6)))) -> 5 | AG23: =IF(P23="none",0,IF(P23="unknown",5,Weights!$B$4)) -> 15 | AH23: =IF(K23="",4,IF(AND(K23>=Weights!$B$13,K23<=Weights!$B$14),Weights!$B$5,IF(K23>100,15,IF(K23>=20,12,4)))) -> 12 | AI23: =IF(OR(Q23="taken",Q23="sold",Q23="ruled-out"),0,MIN(IF(AND(H23="tourist-hotel",P23="none"),Weights!$B$11,100),AE23+AF23+AG23+AH23)+IF(T23="yes",Weights!$B$10,0)) -> 32 | AJ23: not-contacted | AK23: Jul 16 2026 (report)
A24: =RANK(AI24,$AI$2:$AI$70) -> 27 | B24: Ferns Hotel — price-cut, income-hungry | C24: 415–417 15th St, Downtown Oakland | D24: Downtown Oakland | E24: East Bay | F24: 45 | G24: est. by neighborhood (geocode in portal) | H24: sro-hotel | I24: 33 | J24: 1 | K24: =IF(I24="","",I24*J24) -> 33 | L24: 950 | M24: 1200 | N24: =IF(L24="","",ROUND((L24+M24)/2/J24,0)) -> 1075 | O24: =IF(N24="","",N24*Weights!$B$12) -> 48375 | P24: communal | Q24: on-market | R24: Bargain / distressed | T24: unknown | W24: $4.32M, cut from $4.98M; gross income only $377k/yr | X24: Lowball master lease ≈ $800–900/room matches current gross | Y24: Fred Lewis | Z24: (209) 522-9999 | AA24: info@hotdealsoakland.com | AB24: Bargains / distressed | AC24: Offering brochure (PDF): https://images3.loopnet.com/d2/fcQavuW6QnYRr5iaTP1pTcdxUIxr5FCekoZrGvUWJoQ/document.pdf | AD24: Recently rehabbed (20 units redone, new boiler, solar), 1 block to 19th St BART. Broker Fred Lewis, (209) 522-9999. A master lease at $800–900/room roughly equals what the whole building earns today. | AE24: =IF(LEFT(E24,2)="SF",IF(F24="",0,Weights!$B$2*MAX(0,MIN(1,(Weights!$B$9-F24)/(Weights!$B$9-Weights!$B$8)))),0) -> 0 | AF24: =IF(N24="",5,Weights!$B$3*MAX(0,MIN(1,(Weights!$B$7-N24)/(Weights!$B$7-Weights!$B$6)))) -> 28.125 | AG24: =IF(P24="none",0,IF(P24="unknown",5,Weights!$B$4)) -> 15 | AH24: =IF(K24="",4,IF(AND(K24>=Weights!$B$13,K24<=Weights!$B$14),Weights!$B$5,IF(K24>100,15,IF(K24>=20,12,4)))) -> 12 | AI24: =IF(OR(Q24="taken",Q24="sold",Q24="ruled-out"),0,MIN(IF(AND(H24="tourist-hotel",P24="none"),Weights!$B$11,100),AE24+AF24+AG24+AH24)+IF(T24="yes",Weights!$B$10,0)) -> 55.125 | AJ24: not-contacted | AK24: Jul 16 2026 (report)
A25: =RANK(AI25,$AI$2:$AI$70) -> 63 | B25: Alameda Point BEQ — city signs as-is 5-yr leases | C25: Alameda Point (former Naval Air Station), Alameda | D25: Alameda | E25: East Bay | F25: 70 | G25: est. by neighborhood (geocode in portal) | H25: dorm | I25: 80 | J25: 2 | K25: =IF(I25="","",I25*J25) -> 160 | N25: =IF(L25="","",ROUND((L25+M25)/2/J25,0)) | O25: =IF(N25="","",N25*Weights!$B$12) | P25: unknown | Q25: dark | R25: Bargain / distressed | S25: expansion | T25: no | W25: City-owned, parked in 'Phase 2 future transactions' = unprogrammed | X25: Call JLL: Francisco Torres (510) 213-3580 / Kristi Childers (510) 812-2878 | Y25: JLL: Francisco Torres / Kristi Childers · property mgmt | Z25: (510) 213-3580 / (510) 812-2878 · (510) 749-0304 | AA25: alamedapoint@lpc.com | AB25: Bargains / distressed | AC25: Alameda Point leasing: https://www.alamedapoint.co/leasing Council preview, Jan 2026: https://alamedapost.com/news/january-20-city-council-preview/ | AD25: The city already signs market-rate as-is 5-year leases at the Point (e.g. Kai Concepts, Bldg 168). A barracks building is the exact format needed; expect condition/entitlement work. Also trace the never-used former Navy BOQ at Todd St & Pan Am Way (sold by the school district in 2021, owner unknown). | AE25: =IF(LEFT(E25,2)="SF",IF(F25="",0,Weights!$B$2*MAX(0,MIN(1,(Weights!$B$9-F25)/(Weights!$B$9-Weights!$B$8)))),0) -> 0 | AF25: =IF(N25="",5,Weights!$B$3*MAX(0,MIN(1,(Weights!$B$7-N25)/(Weights!$B$7-Weights!$B$6)))) -> 5 | AG25: =IF(P25="none",0,IF(P25="unknown",5,Weights!$B$4)) -> 5 | AH25: =IF(K25="",4,IF(AND(K25>=Weights!$B$13,K25<=Weights!$B$14),Weights!$B$5,IF(K25>100,15,IF(K25>=20,12,4)))) -> 15 | AI25: =IF(OR(Q25="taken",Q25="sold",Q25="ruled-out"),0,MIN(IF(AND(H25="tourist-hotel",P25="none"),Weights!$B$11,100),AE25+AF25+AG25+AH25)+IF(T25="yes",Weights!$B$10,0)) -> 25 | AJ25: not-contacted | AK25: Jul 16 2026 (report)
A26: =RANK(AI26,$AI$2:$AI$70) -> 65 | B26: 3700 California St — vacant hospital campus, years of runway | C26: Presidio Heights, SF (former CPMC campus) | D26: Presidio Heights | E26: SF-other | F26: 55 | G26: est. by neighborhood (geocode in portal) | H26: campus | J26: 1 | K26: =IF(I26="","",I26*J26) | N26: =IF(L26="","",ROUND((L26+M26)/2/J26,0)) | O26: =IF(N26="","",N26*Weights!$B$12) | P26: unknown | Q26: dark | R26: Bargain / distressed | S26: q1-2027 | T26: no | W26: Owner Prado Group still in environmental review — no construction start | X26: Pitch Prado Group an interim activation lease | Y26: Prado Group | Z26: — | AA26: pradogroup.com contact · 3700calsf.com | AB26: Bargains / distressed | AC26: SF YIMBY — EIR: https://sfyimby.com/2025/04/environmental-review-available-for-3700-california-street-in-presidio-heights-san-francisco.html SF Standard: https://sfstandard.com/2024/04/20/prado-group-redeveloping-hospitals-presidio-heights/ | AD26: Multi-year-vacant campus with a carrying-cost-burdened owner and 1–2+ years before demolition — textbook interim master lease. Caveat: hospital floorplates need change-of-use work; target the support/office buildings first. | AE26: =IF(LEFT(E26,2)="SF",IF(F26="",0,Weights!$B$2*MAX(0,MIN(1,(Weights!$B$9-F26)/(Weights!$B$9-Weights!$B$8)))),0) -> 0 | AF26: =IF(N26="",5,Weights!$B$3*MAX(0,MIN(1,(Weights!$B$7-N26)/(Weights!$B$7-Weights!$B$6)))) -> 5 | AG26: =IF(P26="none",0,IF(P26="unknown",5,Weights!$B$4)) -> 5 | AH26: =IF(K26="",4,IF(AND(K26>=Weights!$B$13,K26<=Weights!$B$14),Weights!$B$5,IF(K26>100,15,IF(K26>=20,12,4)))) -> 4 | AI26: =IF(OR(Q26="taken",Q26="sold",Q26="ruled-out"),0,MIN(IF(AND(H26="tourist-hotel",P26="none"),Weights!$B$11,100),AE26+AF26+AG26+AH26)+IF(T26="yes",Weights!$B$10,0)) -> 14 | AJ26: not-contacted | AK26: Jul 16 2026 (report)
A27: =RANK(AI27,$AI$2:$AI$70) -> 65 | B27: SF Archdiocese liquidation — get in before the brokers | C27: Citywide SF + St. Vincent's, San Rafael | D27: Citywide / San Rafael | E27: North Bay | F27: 90 | G27: est. by neighborhood (geocode in portal) | H27: campus | J27: 1 | K27: =IF(I27="","",I27*J27) | N27: =IF(L27="","",ROUND((L27+M27)/2/J27,0)) | O27: =IF(N27="","",N27*Weights!$B$12) | P27: unknown | Q27: dark | R27: Bargain / distressed | S27: q1-2027 | T27: no | W27: $395M abuse settlement (June 30, 2026) forces sales over 6–18 months | X27: Archdiocese Real Property office + Catholic Charities (Tony Alioto, AVAlioto@CatholicCharitiesSF.org) | Y27: Catholic Charities: Tony Alioto; Archdiocese Real Property office | Z27: — | AA27: AVAlioto@CatholicCharitiesSF.org | AB27: Bargains / distressed | AC27: ABC — settlement: https://abcnews.com/US/wireStory/san-francisco-archdiocese-agrees-pay-395-million-settle-134323951 Catholic Charities: https://catholiccharitiessf.org/st-vincents-school-for-boys/housing-site/ KTVU — surplus list: https://www.ktvu.com/news/advocates-of-sex-abuse-victims-want-sf-archdiocese-to-sell-unused-property-as-reparations | AD27: No public sale list exists yet — which is exactly why to call now. Flagged surplus: St. Thomas the Apostle school (~$25M), Menlo Park seminary acreage, St. Vincent's San Rafael (development 5+ years out; historic dorm buildings could take an interim lease). Oakland Diocese settled $143.5M — same dynamic. | AE27: =IF(LEFT(E27,2)="SF",IF(F27="",0,Weights!$B$2*MAX(0,MIN(1,(Weights!$B$9-F27)/(Weights!$B$9-Weights!$B$8)))),0) -> 0 | AF27: =IF(N27="",5,Weights!$B$3*MAX(0,MIN(1,(Weights!$B$7-N27)/(Weights!$B$7-Weights!$B$6)))) -> 5 | AG27: =IF(P27="none",0,IF(P27="unknown",5,Weights!$B$4)) -> 5 | AH27: =IF(K27="",4,IF(AND(K27>=Weights!$B$13,K27<=Weights!$B$14),Weights!$B$5,IF(K27>100,15,IF(K27>=20,12,4)))) -> 4 | AI27: =IF(OR(Q27="taken",Q27="sold",Q27="ruled-out"),0,MIN(IF(AND(H27="tourist-hotel",P27="none"),Weights!$B$11,100),AE27+AF27+AG27+AH27)+IF(T27="yes",Weights!$B$10,0)) -> 14 | AJ27: not-contacted | AK27: Jul 16 2026 (report)
A28: =RANK(AI28,$AI$2:$AI$70) -> 38 | B28: SureStay Plus Richmond — active default, 108 rooms | C28: Richmond (near I-80, ~20 min to Oakland) | D28: Richmond (East Bay) | E28: East Bay | F28: 75 | G28: est. by neighborhood (geocode in portal) | H28: tourist-hotel | I28: 108 | J28: 1 | K28: =IF(I28="","",I28*J28) -> 108 | L28: 900 | M28: 1300 | N28: =IF(L28="","",ROUND((L28+M28)/2/J28,0)) -> 1100 | O28: =IF(N28="","",N28*Weights!$B$12) -> 49500 | P28: none | Q28: receivership | R28: Bargain / distressed | T28: no | W28: In default on an $11.6M loan now | X28: Watch for receiver/auction; pitch the lender | Y28: monitor — pitch whoever takes the keys | Z28: — | AA28: via Bisnow coverage / county filings | AB28: Bargains / distressed | AC28: Bisnow, Jul 2026: https://www.bisnow.com/san-francisco/news/hotel/bay-area-hotel-market-recovering-distress-still-looms-135317 | AD28: Live distress in progress — the next Hyatt House-style giveaway could be here. Location is the tradeoff; monitor and pitch whoever takes the keys. | AE28: =IF(LEFT(E28,2)="SF",IF(F28="",0,Weights!$B$2*MAX(0,MIN(1,(Weights!$B$9-F28)/(Weights!$B$9-Weights!$B$8)))),0) -> 0 | AF28: =IF(N28="",5,Weights!$B$3*MAX(0,MIN(1,(Weights!$B$7-N28)/(Weights!$B$7-Weights!$B$6)))) -> 27.5 | AG28: =IF(P28="none",0,IF(P28="unknown",5,Weights!$B$4)) -> 0 | AH28: =IF(K28="",4,IF(AND(K28>=Weights!$B$13,K28<=Weights!$B$14),Weights!$B$5,IF(K28>100,15,IF(K28>=20,12,4)))) -> 15 | AI28: =IF(OR(Q28="taken",Q28="sold",Q28="ruled-out"),0,MIN(IF(AND(H28="tourist-hotel",P28="none"),Weights!$B$11,100),AE28+AF28+AG28+AH28)+IF(T28="yes",Weights!$B$10,0)) -> 40 | AJ28: not-contacted | AK28: Jul 16 2026 (report)
A29: =RANK(AI29,$AI$2:$AI$70) -> 38 | B29: Hotel Whitcomb floors — Blackstone wants an interim operator | C29: 1231 Market St, Mid-Market SF | D29: Civic Center | E29: SF-priority | F29: 3 | G29: est. by neighborhood (geocode in portal) | H29: tourist-hotel | I29: 80 | J29: 1 | K29: =IF(I29="","",I29*J29) -> 80 | L29: 1500 | M29: 2200 | N29: =IF(L29="","",ROUND((L29+M29)/2/J29,0)) -> 1850 | O29: =IF(N29="","",N29*Weights!$B$12) -> 83250 | P29: none | Q29: receivership | R29: Bargain / distressed | S29: q1-2027;expansion | T29: unknown | W29: Blackstone foreclosed Oct 2025; 'exploring new operators before offloading' | X29: Pitch Blackstone Mortgage Trust as the interim operator | Y29: Blackstone Real Estate — asset mgmt; 'exploring new operators' | Z29: — | AA29: via Blackstone RE press office / Hotel Whitcomb GM | AB29: Report §6e | AC29: SF Standard, Oct 2025: https://sfstandard.com/2025/10/02/hotel-whitcomb-mid-market-blackstone-rfr/ | AD29: UPGRADED from ruled-out: the lender is publicly looking for exactly what we are — an interim operator for a building that already housed people for 33 months (city shelter contract, ~$108M). Take a floor block, not the whole 459. Condition needs inspection after years dark. | AE29: =IF(LEFT(E29,2)="SF",IF(F29="",0,Weights!$B$2*MAX(0,MIN(1,(Weights!$B$9-F29)/(Weights!$B$9-Weights!$B$8)))),0) -> 35 | AF29: =IF(N29="",5,Weights!$B$3*MAX(0,MIN(1,(Weights!$B$7-N29)/(Weights!$B$7-Weights!$B$6)))) -> 8.75 | AG29: =IF(P29="none",0,IF(P29="unknown",5,Weights!$B$4)) -> 0 | AH29: =IF(K29="",4,IF(AND(K29>=Weights!$B$13,K29<=Weights!$B$14),Weights!$B$5,IF(K29>100,15,IF(K29>=20,12,4)))) -> 12 | AI29: =IF(OR(Q29="taken",Q29="sold",Q29="ruled-out"),0,MIN(IF(AND(H29="tourist-hotel",P29="none"),Weights!$B$11,100),AE29+AF29+AG29+AH29)+IF(T29="yes",Weights!$B$10,0)) -> 40 | AJ29: not-contacted | AK29: Jul 16 2026 (report)
A30: =RANK(AI30,$AI$2:$AI$70) -> 36 | B30: Salvation Army McFee Center — 96-bed building in entitlement limbo | C30: 1500 Valencia St + 3500 Cesar Chavez, Mission, SF | D30: Mission | E30: SF-other | F30: 35 | G30: est. by neighborhood (geocode in portal) | H30: dorm | I30: 48 | J30: 2 | K30: =IF(I30="","",I30*J30) -> 96 | N30: =IF(L30="","",ROUND((L30+M30)/2/J30,0)) | O30: =IF(N30="","",N30*Weights!$B$12) | P30: communal | Q30: on-market | R30: Bargain / distressed | S30: q1-2027;expansion | T30: no | W30: Listed Feb 2026 at $58M (land play) — interim income wanted | X30: Broker: Catherine Marcus Bassick, Douglas Elliman Commercial | Y30: Catherine Bassick — Douglas Elliman (listing broker) | Z30: — | AA30: elliman.com agent profile | AB30: Report §6e | AC30: SF Standard: https://sfstandard.com/2026/02/19/salvation-army-site-listing-mission/ TRD: https://therealdeal.com/san-francisco/2026/02/20/san-francisco-salvation-army-site-for-sale-for-58-million/ | AD30: $58M is a land-value ask that will take years to close and entitle. A seller holding a 96-bed residential building through a long sale/entitlement cycle is a textbook interim-master-lease counterparty — holding income strengthens their sale. | AE30: =IF(LEFT(E30,2)="SF",IF(F30="",0,Weights!$B$2*MAX(0,MIN(1,(Weights!$B$9-F30)/(Weights!$B$9-Weights!$B$8)))),0) -> 10 | AF30: =IF(N30="",5,Weights!$B$3*MAX(0,MIN(1,(Weights!$B$7-N30)/(Weights!$B$7-Weights!$B$6)))) -> 5 | AG30: =IF(P30="none",0,IF(P30="unknown",5,Weights!$B$4)) -> 15 | AH30: =IF(K30="",4,IF(AND(K30>=Weights!$B$13,K30<=Weights!$B$14),Weights!$B$5,IF(K30>100,15,IF(K30>=20,12,4)))) -> 12 | AI30: =IF(OR(Q30="taken",Q30="sold",Q30="ruled-out"),0,MIN(IF(AND(H30="tourist-hotel",P30="none"),Weights!$B$11,100),AE30+AF30+AG30+AH30)+IF(T30="yes",Weights!$B$10,0)) -> 42 | AJ30: not-contacted | AK30: Jul 16 2026 (report)
